Workbook
Name _56F9DC9755BA473782653E2940F9FormId: "V6Pjw_ttoUmOduXsd8ZfwTMuH55bJJ5DuWEHs2W93ZZUNE1RQzRLSURHTVRORFlNVjEwS1I5TktLVi4u"
Name _56F9DC9755BA473782653E2940F9ResponseSheet: "Form1"
Name _56F9DC9755BA473782653E2940F9SourceDocId: "{5996ccd8-9206-40fc-b022-c89f400779c7}"

Sheet _56F9DC9755BA473782653E2940F9
A1: V6Pjw_ttoUmOduXsd8ZfwTMuH55bJJ5DuWEHs2W93ZZUNE1RQzRLSURHTVRORFlNVjEwS1I5TktLVi4u
A2: Form1
A3: {5996ccd8-9206-40fc-b022-c89f400779c7}

Sheet Danh sách khối 3
A1: STT | B1: MNV | C1: Họ tên | D1: Ngày sinh | E1: Tháng sinh | F1: Đơn vị cấp 4 | G1: Đơn vị cấp 5 | H1: Đơn vị cấp 6 | I1: Chức danh | J1: Diện đối tượng | K1: Ngày vào tập đoàn | L1: Vị trí
A2: 1 | B2: 116188 | C2: Khương Duy | D2: 29714 | E2: 5 | F2: Khối 3 - TCT CNC | G2: Ban Giám đốc | H2: Thủ trưởng đơn vị | I2: Phó Giám đốc Khối | J2: Sỹ quan | K2: 40535
A3: 2 | B3: 009646 | C3: Phạm Duy Lập | D3: 26832 | E3: 6 | F3: Khối 3 - TCT CNC | G3: Ban Giám đốc | H3: Thủ trưởng đơn vị | I3: Phó Giám đốc Khối | J3: Sỹ quan | K3: 37561
A4: 3 | B4: 448235 | C4: Nguyễn Đình Minh | D4: 35623 | E4: 7 | F4: Khối 3 - TCT CNC | G4: Phòng Kinh doanh | H4: Trợ lý nghiệp vụ | I4: Nhân viên kinh doanh | J4: Hợp đồng lao động | K4: 45005
A5: 4 | B5: 276311 | C5: Trần Quốc Dũng | D5: 32076 | E5: 10 | F5: Khối 3 - TCT CNC | G5: Phòng Kinh doanh | H5: Trợ lý nghiệp vụ | I5: Nhân viên kinh doanh | J5: Hợp đồng lao động | K5: 44170
A6: 5 | B6: 435196 | C6: Lâm Phương Anh | D6: 36969 | E6: 3 | F6: Khối 3 - TCT CNC | G6: Phòng Kinh doanh | H6: Trợ lý nghiệp vụ | I6: Nhân viên Marketing | J6: Hợp đồng lao động | K6: 44763
A7: 6 | B7: 427204 | C7: Nguyễn Thị Phương Anh | D7: 36456 | E7: 10 | F7: Khối 3 - TCT CNC | G7: Phòng Kinh doanh | H7: Trợ lý nghiệp vụ | I7: Nhân viên kinh doanh | J7: Hợp đồng lao động | K7: 44600
A8: 7 | B8: 242809 | C8: Nguyễn Phú Hoàng Hà | D8: 33558 | E8: 11 | F8: Khối 3 - TCT CNC | G8: Phòng Kinh doanh | H8: Trợ lý nghiệp vụ | I8: Chuyên viên kinh doanh | J8: Hợp đồng lao động | K8: 43577
A9: 8 | B9: 196336 | C9: Dương Thúy Hằng | D9: 33332 | E9: 4 | F9: Khối 3 - TCT CNC | G9: Phòng Kinh doanh | H9: Trợ lý nghiệp vụ | I9: Nhân viên Kinh doanh | J9: Hợp đồng lao động | K9: 41885
A10: 9 | B10: 435960 | C10: Lê Khánh Ly | D10: 37165 | E10: 10 | F10: Khối 3 - TCT CNC | G10: Phòng Kinh doanh | H10: Trợ lý nghiệp vụ | I10: Nhân viên Marketing | J10: Hợp đồng lao động | K10: 44774
A11: 10 | B11: 007589 | C11: Phạm Minh Nghĩa | D11: 29535 | E11: 11 | F11: Khối 3 - TCT CNC | G11: Phòng Kinh doanh | H11: Lãnh đạo phòng | I11: Phó phòng Kinh doanh | J11: Quân nhân chuyên nghiệp | K11: 37712
A12: 11 | B12: 209509 | C12: Nguyễn Thị Mai Anh | D12: 35000 | E12: 10 | F12: Khối 3 - TCT CNC | G12: Phòng Kinh doanh | H12: Trợ lý nghiệp vụ | I12: Nhân viên Kinh doanh | J12: Hợp đồng lao động | K12: 42795
A13: 12 | B13: 452469 | C13: Nguyễn Thị Thu Hiền | D13: 36163 | E13: 1 | F13: Khối 3 - TCT CNC | G13: Phòng Quản lý chất lượng | H13: Bộ phận Kiểm soát chất lượng | I13: Kỹ sư Kiểm định phần mềm | J13: Hợp đồng lao động | K13: 45071
A14: 13 | B14: 243025 | C14: Ngô Thị Yến Linh | D14: 34915 | E14: 8 | F14: Khối 3 - TCT CNC | G14: Phòng Quản lý chất lượng | H14: Bộ phận Kiểm soát chất lượng | I14: Kỹ sư Kiểm định phần mềm | J14: Hợp đồng lao động | K14: 43587 | L14: HCM
A15: 14 | B15: 196208 | C15: Phí Thị Thu Giang | D15: 33352 | E15: 4 | F15: Khối 3 - TCT CNC | G15: Phòng Quản lý chất lượng | H15: Bộ phận Kiểm soát chất lượng | I15: Kỹ sư kiểm định phần mềm | J15: Hợp đồng lao động | K15: 41885
A16: 15 | B16: 440214 | C16: Nguyễn Thị Lan Anh | D16: 36871 | E16: 12 | F16: Khối 3 - TCT CNC | G16: Phòng Quản lý chất lượng | H16: Bộ phận Kiểm soát chất lượng | I16: Kỹ sư Kiểm định phần mềm | J16: Hợp đồng lao động | K16: 44859 | L16: HCM
A17: 16 | B17: 232734 | C17: Chu Thị Ánh Hồng | D17: 34780 | E17: 3 | F17: Khối 3 - TCT CNC | G17: Phòng Quản lý chất lượng | H17: Bộ phận Kiểm soát chất lượng | I17: Kỹ sư Kiểm định phần mềm | J17: Hợp đồng lao động | K17: 43269
A18: 17 | B18: 267488 | C18: Phạm Thị Phương Ngân | D18: 34609 | E18: 10 | F18: Khối 3 - TCT CNC | G18: Phòng Quản lý chất lượng | H18: Bộ phận Đảm bảo chất lượng | I18: Kỹ sư Đảm bảo chất lượng | J18: Hợp đồng lao động | K18: 43963
A19: 18 | B19: 271575 | C19: Lê Thị Lan Hương | D19: 32669 | E19: 6 | F19: Khối 3 - TCT CNC | G19: Phòng Quản lý chất lượng | H19: Bộ phận Đảm bảo chất lượng | I19: Kỹ sư Đảm bảo chất lượng | J19: Hợp đồng lao động | K19: 44060
A20: 19 | B20: 176573 | C20: Diệp Thị Tư | D20: 33538 | E20: 10 | F20: Khối 3 - TCT CNC | G20: Phòng Quản lý chất lượng | H20: Lãnh đạo phòng | I20: Phó phòng Quản lý chất lượng | J20: Hợp đồng lao động | K20: 41584
A21: 20 | B21: 273678 | C21: Hoàng Thị Quỳnh | D21: 35194 | E21: 5 | F21: Khối 3 - TCT CNC | G21: Phòng Quản lý chất lượng | H21: Bộ phận Kiểm soát chất lượng | I21: Kỹ sư Kiểm định phần mềm | J21: Hợp đồng lao động | K21: 44105
A22: 21 | B22: 204893 | C22: Nguyễn Ngọc Mai Ngân | D22: 33471 | E22: 8 | F22: Khối 3 - TCT CNC | G22: Phòng Tổng hợp | H22: Bộ phận Quản lý dự án | I22: Nhân viên Quản lý Dự án | J22: Hợp đồng lao động | K22: 42037
A23: 22 | B23: 273438 | C23: Nguyễn Thị Hạnh Linh | D23: 34913 | E23: 8 | F23: Khối 3 - TCT CNC | G23: Phòng Tổng hợp | H23: Bộ phận Quản lý dự án | I23: Nhân viên Quản lý Dự án | J23: Hợp đồng lao động | K23: 44099
A24: 23 | B24: 011034 | C24: Nguyễn Thị Luyện | D24: 28776 | E24: 10 | F24: Khối 3 - TCT CNC | G24: Phòng Tổng hợp | H24: Bộ phận Quản lý dự án | I24: Nhân viên Quản lý Dự án | J24: Hợp đồng lao động | K24: 38586 | L24: HCM
A25: 24 | B25: 241353 | C25: Lê Văn Bằng | D25: 32393 | E25: 9 | F25: Khối 3 - TCT CNC | G25: Phòng Tổng hợp | H25: Bộ phận Quản lý dự án | I25: Trợ lý Kế hoạch tổng hợp | J25: Sỹ quan | K25: 43532
A26: 25 | B26: 204328 | C26: Nguyễn Thị Hòa | D26: 32379 | E26: 8 | F26: Khối 3 - TCT CNC | G26: Phòng Tổng hợp | H26: Bộ phận Quản lý dự án | I26: Nhân viên Quản lý Dự án | J26: Hợp đồng lao động | K26: 41997
A27: 26 | B27: 185577 | C27: Nguyễn Thị Nhân | D27: 29535 | E27: 11 | F27: Khối 3 - TCT CNC | G27: Phòng Tổng hợp | H27: Bộ phận Văn phòng | I27: Nhân viên Hành chính Tổng hợp | J27: Hợp đồng lao động | K27: 41681
A28: 27 | B28: 047512 | C28: Trần Nguyễn Dũng | D28: 30510 | E28: 7 | F28: Khối 3 - TCT CNC | G28: Phòng Tổng hợp | H28: Bộ phận Văn phòng | I28: Nhân viên Kế hoạch Tổng hợp | J28: Công nhân viên chức quốc phòng | K28: 39363 | L28: HCM
A29: 28 | B29: 221339 | C29: Dương Hải Vũ | D29: 33845 | E29: 8 | F29: Khối 3 - TCT CNC | G29: Phòng Tổng hợp | H29: Lãnh đạo phòng | I29: Trưởng phòng Tổng hợp | J29: Hợp đồng lao động | K29: 42984
A30: 29 | B30: 249089 | C30: Nguyễn Thị Hương | D30: 33775 | E30: 6 | F30: Khối 3 - TCT CNC | G30: Phòng Tổng hợp | H30: Bộ phận Quản lý dự án | I30: Nhân viên Quản lý Dự án | J30: Hợp đồng lao động | K30: 43720
A31: 31 | B31: 292553 | C31: Phạm Thị Thu Trang | D31: 36284 | E31: 5 | F31: Khối 3 - TCT CNC | G31: Trung tâm Camera | H31: Bộ phận nghiên cứu | I31: Kỹ sư Trí tuệ nhân tạo | J31: Hợp đồng lao động | K31: 44531
A32: 32 | B32: 430886 | C32: Phan Anh Chiến | D32: 36529 | E32: 1 | F32: Khối 3 - TCT CNC | G32: Trung tâm Camera | H32: Bộ phận nghiên cứu | I32: Kỹ sư Trí tuệ nhân tạo | J32: Hợp đồng lao động | K32: 44670
A33: 33 | B33: 193281 | C33: Trương Huy Hoàng | D33: 33873 | E33: 9 | F33: Khối 3 - TCT CNC | G33: Trung tâm Camera | H33: Bộ phận nghiên cứu | I33: Chủ nhiệm đề tài | J33: Hợp đồng lao động | K33: 41834
A34: 34 | B34: 156893 | C34: Nguyễn Bá Tân | D34: 31437 | E34: 1 | F34: Khối 3 - TCT CNC | G34: Trung tâm Camera | H34: Bộ phận nghiên cứu | I34: Kỹ sư trưởng Công nghệ | J34: Hợp đồng lao động | K34: 41421 | L34: HCM
A35: 35 | B35: 443625 | C35: Phạm Duy Giác Nguyên | D35: 36533 | E35: 1 | F35: Khối 3 - TCT CNC | G35: Trung tâm Camera | H35: Bộ phận nghiên cứu | I35: Kỹ sư Trí tuệ nhân tạo | J35: Hợp đồng lao động | K35: 44916
A36: 36 | B36: 441579 | C36: Nguyễn Thị Trang | D36: 36759 | E36: 8 | F36: Khối 3 - TCT CNC | G36: Trung tâm Camera | H36: Bộ phận nghiên cứu | I36: Kỹ sư Trí tuệ nhân tạo | J36: Hợp đồng lao động | K36: 44886
A37: 37 | B37: 454893 | C37: Nguyễn Tống Minh | D37: 37293 | E37: 2 | F37: Khối 3 - TCT CNC | G37: Trung tâm Camera | H37: Bộ phận nghiên cứu | I37: Kỹ sư Trí tuệ nhân tạo | J37: Hợp đồng tập nghề | K37: 45131
A38: 38 | B38: 439614 | C38: Nguyễn Huy Đức | D38: 36544 | E38: 1 | F38: Khối 3 - TCT CNC | G38: Trung tâm Camera | H38: Bộ phận nghiên cứu | I38: Kỹ sư Lập trình nhúng | J38: Hợp đồng lao động | K38: 44846
A39: 39 | B39: 238618 | C39: Lê Thanh Tùng | D39: 35431 | E39: 1 | F39: Khối 3 - TCT CNC | G39: Trung tâm Camera | H39: Bộ phận nghiên cứu | I39: Kỹ sư Phát triển phần mềm nhúng | J39: Hợp đồng lao động | K39: 43405
A40: 40 | B40: 240799 | C40: Đặng Thanh Tùng | D40: 35579 | E40: 5 | F40: Khối 3 - TCT CNC | G40: Trung tâm Camera | H40: Bộ phận nghiên cứu | I40: Kỹ sư Phát triển phần mềm | J40: Hợp đồng lao động | K40: 43511
...

Sheet Danh sách yêu cầu thanh toán
A1: ID | B1: Start time | C1: Completion time | D1: Email | E1: Name | F1: Last modified time | G1: Tên CBCNV | H1: Mã NV | I1: Chức vụ | J1: Đơn vị | K1: Chọn phúc lợi yêu cầu | L1: Chúc mừng CBNV | M1: Thân nhân của bạn đồng chí là | N1: Nơi điều trị | O1: Loại hồ sơ, giấy tờ kèm theo | P1: Số giấy tờ | Q1: Xác nhận thông tin | R1: Họ và tên thân nhân | S1: Họ và tên thân nhân: | T1: Thân nhân của bạn đồng chí là: | U1: Ngày mất2
A2: 123 | B2: 45831.479 | C2: 45831.481 | D2: anonymous | G2: Phí Thị Thu Giang | H2: 196208 | I2: Kỹ sư Kiểm định phần mềm | J2: Phòng QLCL | K2: thăm hỏi thân nhân CBNV | M2: bố đẻ | N2: Bệnh viện ĐK Y học cổ truyền Hà Nội | O2: Giấy ra viện | P2: 27/05/2025 | R2: Phí Văn Thành
A3: 124 | B3: 45831.481 | C3: 45831.482 | D3: anonymous | G3: Lê Thị Lan Hương | H3: 271575 | I3: Kỹ sư Đảm bảo chất lượng | J3: Phòng QLCL | K3: thăm hỏi thân nhân CBNV | M3: bố chồng | N3: Bệnh viện Đại học Y Hà Nội | O3: Giấy ra viện | P3: 06/06/2025 | R3: Đinh Văn Lừng
A4: 125 | B4: 45831.482 | C4: 45831.484 | D4: anonymous | G4: Nguyễn Thị Phương Anh | H4: 427204 | I4: Nhân viên kinh doanh | J4: Phòng Kinh doanh | K4: thăm hỏi thân nhân CBNV | M4: mẹ đẻ | N4: Bệnh viện E | O4: Giấy ra viện | P4: 29/05/2025 | R4: Nguyễn Thị Bích Thủy
A5: 126 | B5: 45831.484 | C5: 45831.485 | D5: anonymous | G5: Trần Văn Bằng | H5: 245555 | I5: Kỹ sư Phát triển phần mềm | J5: Trung tâm Camera | K5: thăm hỏi thân nhân CBNV | M5: bố đẻ | N5: Bệnh viện ĐK tỉnh Quảng Trị | O5: Giấy ra viện | P5: 22/05/2025 | R5: Trần Văn Triều
B8: =

Sheet CD - PL in cho ký nhận
A1: TỔNG CÔNG TY CÔNG NGHIỆP CÔNG NGHỆ CAO VIETTEL
A2: CÔNG ĐOÀN CƠ SỞ
A4: ="DANH SÁCH CHI TIỀN CÔNG ĐOÀN PHÚC LỢI CĐBP KHỐI 3 THÁNG "&MONTH('Danh sách yêu cầu thanh toán'!C5)&" "&YEAR('Danh sách yêu cầu thanh toán'!C5) -> DANH SÁCH CHI TIỀN CÔNG ĐOÀN PHÚC LỢI CĐBP KHỐI 3 THÁNG 6 2025
A5: ="(Kèm theo phiếu chi số PC_CĐCS số ngày / /"&YEAR('Danh sách yêu cầu thanh toán'!C5)&")" -> (Kèm theo phiếu chi số PC_CĐCS số ngày / /2025)
A7: TT | B7: MÃ NV | C7: HỌ VÀ TÊN | D7: NỘI DUNG | E7: ĐƠN VỊ | F7: CÔNG ĐOÀN | G7: PHÚC LỢI | H7: THUẾ TNCN | I7: THỰC NHẬN (VNĐ) | J7: HỌ TÊN | K7: QUAN HỆ GIA ĐÌNH | L7: HỒ SƠ KÈM THEO | M7: KÝ NHẬN (Ký và ghi rõ họ tên)
A8: =ROWS($B$8:B8) -> 1 | B8: 244757 | C8: =IFERROR(VLOOKUP(B8,'Danh sách khối 3'!$B$2:$M$203,2,FALSE),"") -> Đỗ Thị Xuân | D8: =IF(B8="","",IF('Danh sách yêu cầu thanh toán'!K2="chúc mừng CBNV","Chi kinh phí CĐ, PL chúc mừng đ/c "&C8&" "&'Danh sách yêu cầu thanh toán'!L2,IF('Danh sách yêu cầu thanh toán'!K2="thăm hỏi CBNV","Chi kinh phí CĐ, PL thăm hỏi đ/c "&C8&" ốm",IF('Danh sách yêu cầu thanh toán'!K2="viếng CBNV từ trần","Chi kinh phí CĐ, PL viếng đ/c "&C8&" từ trần",IF('Danh sách yêu cầu thanh toán'!K2="viếng thân nhân CBNV từ trần","Chi kinh phí CĐ, PL viếng "& 'Danh sách yêu cầu thanh toán'!#REF!&" đ/c "&C8&" từ trần","Chi kinh phí CĐ, PL thăm hỏi "&'Danh sách yêu cầu thanh toán'!M2&" đ/c "&C8&" ốm"))))) -> Chi kinh phí CĐ, PL thăm hỏi bố đẻ đ/c Đỗ Thị Xuân ốm | E8: =IFERROR(VLOOKUP(B8,'Danh sách khối 3'!$B$2:$M$203,6,FALSE),"") -> Trung tâm Nền tảng IOT | F8: =IF(B8="","",IF('Danh sách yêu cầu thanh toán'!K4="chúc mừng CBNV",1000000,IF('Danh sách yêu cầu thanh toán'!K4="viếng CBNV từ trần",1500000,IF('Danh sách yêu cầu thanh toán'!K4="viếng thân nhân CBNV từ trần",1500000,500000)))) -> 500000 | G8: =IF(B8="","",IF('Danh sách yêu cầu thanh toán'!K4="chúc mừng CBNV",1500000,IF('Danh sách yêu cầu thanh toán'!K4="viếng CBNV từ trần",2500000,IF('Danh sách yêu cầu thanh toán'!K4="viếng thân nhân CBNV từ trần",2000000,1000000)))) -> 1000000 | I8: =IFERROR(F8+G8-H8,"") -> 1500000 | J8: =IF('Danh sách yêu cầu thanh toán'!G2="","",IF(AND('Danh sách yêu cầu thanh toán'!R2="",'Danh sách yêu cầu thanh toán'!S2=""),'Danh sách yêu cầu thanh toán'!G2,'Danh sách yêu cầu thanh toán'!R2&'Danh sách yêu cầu thanh toán'!S2)) -> Phí Văn Thành | K8: =IF(B8="","",PROPER(IF(AND('Danh sách yêu cầu thanh toán'!M2="",'Danh sách yêu cầu thanh toán'!T2=""),"bản thân",'Danh sách yêu cầu thanh toán'!M2&'Danh sách yêu cầu thanh toán'!T2))) -> Bố Đẻ | L8: =IF(B8="","",IF(OR('Danh sách yêu cầu thanh toán'!O2="Giấy chứng sinh",'Danh sách yêu cầu thanh toán'!O2="Giấy khai sinh"),'Danh sách yêu cầu thanh toán'!O2&" số "&'Danh sách yêu cầu thanh toán'!P2,IF(OR('Danh sách yêu cầu thanh toán'!O2="Giấy đăng ký kết hôn",'Danh sách yêu cầu thanh toán'!O2="Thiệp cưới",'Danh sách yêu cầu thanh toán'!O2="Giấy ra viện",'Danh sách yêu cầu thanh toán'!O2="Giấy nhập viện",'Danh sách yêu cầu thanh toán'!O2="Giấy chứng nhận phẫu thuật"),'Danh sách yêu cầu thanh toán'!O2&" ngày "&'Danh sách yêu cầu thanh toán'!P2,"Cáo phó ngày "&'Danh sách yêu cầu thanh toán'!U2))) -> Giấy ra viện ngày 27/05/2025
A9: =ROWS($B$8:B9) -> 2 | B9: 204328 | C9: =IFERROR(VLOOKUP(B9,'Danh sách khối 3'!$B$2:$M$203,2,FALSE),"") -> Nguyễn Thị Hòa | D9: =IF(B9="","",IF('Danh sách yêu cầu thanh toán'!K3="chúc mừng CBNV","Chi kinh phí CĐ, PL chúc mừng đ/c "&C9&" "&'Danh sách yêu cầu thanh toán'!L3,IF('Danh sách yêu cầu thanh toán'!K3="thăm hỏi CBNV","Chi kinh phí CĐ, PL thăm hỏi đ/c "&C9&" ốm",IF('Danh sách yêu cầu thanh toán'!K3="viếng CBNV từ trần","Chi kinh phí CĐ, PL viếng đ/c "&C9&" từ trần",IF('Danh sách yêu cầu thanh toán'!K3="viếng thân nhân CBNV từ trần","Chi kinh phí CĐ, PL viếng "& 'Danh sách yêu cầu thanh toán'!#REF!&" đ/c "&C9&" từ trần","Chi kinh phí CĐ, PL thăm hỏi "&'Danh sách yêu cầu thanh toán'!M3&" đ/c "&C9&" ốm"))))) -> Chi kinh phí CĐ, PL thăm hỏi bố chồng đ/c Nguyễn Thị Hòa ốm | E9: =IFERROR(VLOOKUP(B9,'Danh sách khối 3'!$B$2:$M$203,6,FALSE),"") -> Phòng Tổng hợp | F9: =IF(B9="","",IF('Danh sách yêu cầu thanh toán'!K5="chúc mừng CBNV",1000000,IF('Danh sách yêu cầu thanh toán'!K5="viếng CBNV từ trần",1500000,IF('Danh sách yêu cầu thanh toán'!K5="viếng thân nhân CBNV từ trần",1500000,500000)))) -> 500000 | G9: =IF(B9="","",IF('Danh sách yêu cầu thanh toán'!K5="chúc mừng CBNV",1500000,IF('Danh sách yêu cầu thanh toán'!K5="viếng CBNV từ trần",2500000,IF('Danh sách yêu cầu thanh toán'!K5="viếng thân nhân CBNV từ trần",2000000,1000000)))) -> 1000000 | I9: =IFERROR(F9+G9-H9,"") -> 1500000 | J9: =IF('Danh sách yêu cầu thanh toán'!G3="","",IF(AND('Danh sách yêu cầu thanh toán'!R3="",'Danh sách yêu cầu thanh toán'!S3=""),'Danh sách yêu cầu thanh toán'!G3,'Danh sách yêu cầu thanh toán'!R3&'Danh sách yêu cầu thanh toán'!S3)) -> Đinh Văn Lừng | K9: =IF(B9="","",PROPER(IF(AND('Danh sách yêu cầu thanh toán'!M3="",'Danh sách yêu cầu thanh toán'!T3=""),"bản thân",'Danh sách yêu cầu thanh toán'!M3&'Danh sách yêu cầu thanh toán'!T3))) -> Bố Chồng | L9: =IF(B9="","",IF(OR('Danh sách yêu cầu thanh toán'!O3="Giấy chứng sinh",'Danh sách yêu cầu thanh toán'!O3="Giấy khai sinh"),'Danh sách yêu cầu thanh toán'!O3&" số "&'Danh sách yêu cầu thanh toán'!P3,IF(OR('Danh sách yêu cầu thanh toán'!O3="Giấy đăng ký kết hôn",'Danh sách yêu cầu thanh toán'!O3="Thiệp cưới",'Danh sách yêu cầu thanh toán'!O3="Giấy ra viện",'Danh sách yêu cầu thanh toán'!O3="Giấy nhập viện",'Danh sách yêu cầu thanh toán'!O3="Giấy chứng nhận phẫu thuật"),'Danh sách yêu cầu thanh toán'!O3&" ngày "&'Danh sách yêu cầu thanh toán'!P3,"Cáo phó ngày "&'Danh sách yêu cầu thanh toán'!U3))) -> Giấy ra viện ngày 06/06/2025
A10: =ROWS($B$8:B10) -> 3 | B10: 026567 | C10: Nông Thị Minh Hiến | D10: =IF(B10="","",IF('Danh sách yêu cầu thanh toán'!K4="chúc mừng CBNV","Chi kinh phí CĐ, PL chúc mừng đ/c "&C10&" "&'Danh sách yêu cầu thanh toán'!L4,IF('Danh sách yêu cầu thanh toán'!K4="thăm hỏi CBNV","Chi kinh phí CĐ, PL thăm hỏi đ/c "&C10&" ốm",IF('Danh sách yêu cầu thanh toán'!K4="viếng CBNV từ trần","Chi kinh phí CĐ, PL viếng đ/c "&C10&" từ trần",IF('Danh sách yêu cầu thanh toán'!K4="viếng thân nhân CBNV từ trần","Chi kinh phí CĐ, PL viếng "& 'Danh sách yêu cầu thanh toán'!#REF!&" đ/c "&C10&" từ trần","Chi kinh phí CĐ, PL thăm hỏi "&'Danh sách yêu cầu thanh toán'!M4&" đ/c "&C10&" ốm"))))) -> Chi kinh phí CĐ, PL thăm hỏi mẹ đẻ đ/c Nông Thị Minh Hiến ốm | E10: Phòng Tổng hợp | F10: =IF(B10="","",IF('Danh sách yêu cầu thanh toán'!K6="chúc mừng CBNV",1000000,IF('Danh sách yêu cầu thanh toán'!K6="viếng CBNV từ trần",1500000,IF('Danh sách yêu cầu thanh toán'!K6="viếng thân nhân CBNV từ trần",1500000,500000)))) -> 500000 | G10: =IF(B10="","",IF('Danh sách yêu cầu thanh toán'!K6="chúc mừng CBNV",1500000,IF('Danh sách yêu cầu thanh toán'!K6="viếng CBNV từ trần",2500000,IF('Danh sách yêu cầu thanh toán'!K6="viếng thân nhân CBNV từ trần",2000000,1000000)))) -> 1000000 | I10: =IFERROR(F10+G10-H10,"") -> 1500000 | J10: =IF('Danh sách yêu cầu thanh toán'!G4="","",IF(AND('Danh sách yêu cầu thanh toán'!R4="",'Danh sách yêu cầu thanh toán'!S4=""),'Danh sách yêu cầu thanh toán'!G4,'Danh sách yêu cầu thanh toán'!R4&'Danh sách yêu cầu thanh toán'!S4)) -> Nguyễn Thị Bích Thủy | K10: =IF(B10="","",PROPER(IF(AND('Danh sách yêu cầu thanh toán'!M4="",'Danh sách yêu cầu thanh toán'!T4=""),"bản thân",'Danh sách yêu cầu thanh toán'!M4&'Danh sách yêu cầu thanh toán'!T4))) -> Mẹ Đẻ | L10: =IF(B10="","",IF(OR('Danh sách yêu cầu thanh toán'!O4="Giấy chứng sinh",'Danh sách yêu cầu thanh toán'!O4="Giấy khai sinh"),'Danh sách yêu cầu thanh toán'!O4&" số "&'Danh sách yêu cầu thanh toán'!P4,IF(OR('Danh sách yêu cầu thanh toán'!O4="Giấy đăng ký kết hôn",'Danh sách yêu cầu thanh toán'!O4="Thiệp cưới",'Danh sách yêu cầu thanh toán'!O4="Giấy ra viện",'Danh sách yêu cầu thanh toán'!O4="Giấy nhập viện",'Danh sách yêu cầu thanh toán'!O4="Giấy chứng nhận phẫu thuật"),'Danh sách yêu cầu thanh toán'!O4&" ngày "&'Danh sách yêu cầu thanh toán'!P4,"Cáo phó ngày "&'Danh sách yêu cầu thanh toán'!U4))) -> Giấy ra viện ngày 29/05/2025
A11: =ROWS($B$8:B11) -> 4 | B11: 431909 | C11: =IFERROR(VLOOKUP(B11,'Danh sách khối 3'!$B$2:$M$203,2,FALSE),"") -> Nguyễn Quang Chung | D11: =IF(B11="","",IF('Danh sách yêu cầu thanh toán'!K5="chúc mừng CBNV","Chi kinh phí CĐ, PL chúc mừng đ/c "&C11&" "&'Danh sách yêu cầu thanh toán'!L5,IF('Danh sách yêu cầu thanh toán'!K5="thăm hỏi CBNV","Chi kinh phí CĐ, PL thăm hỏi đ/c "&C11&" ốm",IF('Danh sách yêu cầu thanh toán'!K5="viếng CBNV từ trần","Chi kinh phí CĐ, PL viếng đ/c "&C11&" từ trần",IF('Danh sách yêu cầu thanh toán'!K5="viếng thân nhân CBNV từ trần","Chi kinh phí CĐ, PL viếng "& 'Danh sách yêu cầu thanh toán'!T1&" đ/c "&C11&" từ trần","Chi kinh phí CĐ, PL thăm hỏi "&'Danh sách yêu cầu thanh toán'!M5&" đ/c "&C11&" ốm"))))) -> Chi kinh phí CĐ, PL thăm hỏi bố đẻ đ/c Nguyễn Quang Chung ốm | E11: =IFERROR(VLOOKUP(B11,'Danh sách khối 3'!$B$2:$M$203,6,FALSE),"") -> Trung tâm Camera | F11: =IF(B11="","",IF('Danh sách yêu cầu thanh toán'!K7="chúc mừng CBNV",1000000,IF('Danh sách yêu cầu thanh toán'!K7="viếng CBNV từ trần",1500000,IF('Danh sách yêu cầu thanh toán'!K7="viếng thân nhân CBNV từ trần",1500000,500000)))) -> 500000 | G11: =IF(B11="","",IF('Danh sách yêu cầu thanh toán'!K7="chúc mừng CBNV",1500000,IF('Danh sách yêu cầu thanh toán'!K7="viếng CBNV từ trần",2500000,IF('Danh sách yêu cầu thanh toán'!K7="viếng thân nhân CBNV từ trần",2000000,1000000)))) -> 1000000 | I11: =IFERROR(F11+G11-H11,"") -> 1500000 | J11: =IF('Danh sách yêu cầu thanh toán'!G5="","",IF(AND('Danh sách yêu cầu thanh toán'!R5="",'Danh sách yêu cầu thanh toán'!S5=""),'Danh sách yêu cầu thanh toán'!G5,'Danh sách yêu cầu thanh toán'!R5&'Danh sách yêu cầu thanh toán'!S5)) -> Trần Văn Triều | K11: =IF(B11="","",PROPER(IF(AND('Danh sách yêu cầu thanh toán'!M5="",'Danh sách yêu cầu thanh toán'!T5=""),"bản thân",'Danh sách yêu cầu thanh toán'!M5&'Danh sách yêu cầu thanh toán'!T5))) -> Bố Đẻ | L11: =IF(B11="","",IF(OR('Danh sách yêu cầu thanh toán'!O5="Giấy chứng sinh",'Danh sách yêu cầu thanh toán'!O5="Giấy khai sinh"),'Danh sách yêu cầu thanh toán'!O5&" số "&'Danh sách yêu cầu thanh toán'!P5,IF(OR('Danh sách yêu cầu thanh toán'!O5="Giấy đăng ký kết hôn",'Danh sách yêu cầu thanh toán'!O5="Thiệp cưới",'Danh sách yêu cầu thanh toán'!O5="Giấy ra viện",'Danh sách yêu cầu thanh toán'!O5="Giấy nhập viện",'Danh sách yêu cầu thanh toán'!O5="Giấy chứng nhận phẫu thuật"),'Danh sách yêu cầu thanh toán'!O5&" ngày "&'Danh sách yêu cầu thanh toán'!P5,"Cáo phó ngày "&'Danh sách yêu cầu thanh toán'!U5))) -> Giấy ra viện ngày 22/05/2025
A12: TỔNG CỘNG | F12: =SUM(F8:F11) -> 2000000 | G12: =SUM(G8:G11) -> 4000000 | H12: =SUM(H8:H11) -> 0 | I12: =SUM(I8:I11) -> 6000000
A13: BẰNG CHỮ | F13: Sáu triệu đồng./.
B15: NGƯỜI NHẬN TIỀN | E15: NGƯỜI LẬP PHIẾU | J15: CHỦ TỊCH CĐCS
A20: =I12 -> 6000000 | B20: =RIGHT("000000000000"&ROUND(A20,0),12) -> 000006000000 | C20: 1 | D20: 2 | E20: 3 | F20: 5 | I20: 6 | J20: 7 | M20: 8 | N20: 9 | O20: 10 | P20: 11
C21: =VALUE(MID(B20,C20,1)) -> 0 | D21: =VALUE(MID(B20,D20,1)) -> 0 | E21: =VALUE(MID(B20,E20,1)) -> 0 | F21: =VALUE(MID(B20,F20,1)) -> 0 | I21: =VALUE(MID(B20,I20,1)) -> 6 | J21: =VALUE(MID(B20,J20,1)) -> 0 | M21: =VALUE(MID(B20,M20,1)) -> 0 | N21: =VALUE(MID(B20,N20,1)) -> 0 | O21: =VALUE(MID(B20,O20,1)) -> 0 | P21: =VALUE(MID(B20,P20,1)) -> 0
C22: =SUM(C21:C21) -> 0 | D22: =SUM(C21:D21) -> 0 | E22: =SUM(C21:E21) -> 0 | F22: =SUM(F21:F21) -> 0 | I22: =SUM(F21:I21) -> 6 | J22: =SUM(J21:J21) -> 0 | M22: =SUM(J21:M21) -> 0 | N22: =SUM(J21:N21) -> 0 | O22: =SUM(O21:O21) -> 0 | P22: =SUM(O21:P21) -> 0
C23: =IF(C21=0,"",CHOOSE(C21,"một","hai","ba","bốn","năm","sáu","bảy","tám","chín")) | D23: =IF(D21=0,IF(AND(C21<>0,E21<>0),"lẻ",""),CHOOSE(D21,"mười","hai","ba","bốn","năm","sáu","bảy","tám","chín")) | E23: =IF(E21=0,"",CHOOSE(E21,IF(D21>1,"mốt","một"),"hai","ba","bốn",IF(D21=0,"năm","lăm"),"sáu","bảy","tám","chín")) | F23: =IF(F21=0,IF(AND(#REF!<>0,I21<>0),"lẻ",""),CHOOSE(F21,"mười","hai","ba","bốn","năm","sáu","bảy","tám","chín")) -> #REF! | I23: =IF(I21=0,"",CHOOSE(I21,IF(F21>1,"mốt","một"),"hai","ba","bốn",IF(F21=0,"năm","lăm"),"sáu","bảy","tám","chín")) -> sáu | J23: =IF(J21=0,"",CHOOSE(J21,"một","hai","ba","bốn","năm","sáu","bảy","tám","chín")) | M23: =IF(M21=0,IF(AND(J21<>0,N21<>0),"lẻ",""),CHOOSE(M21,"mười","hai","ba","bốn","năm","sáu","bảy","tám","chín")) | N23: =IF(N21=0,"",CHOOSE(N21,IF(M21>1,"mốt","một"),"hai","ba","bốn",IF(M21=0,"năm","lăm"),"sáu","bảy","tám","chín")) | O23: =IF(O21=0,"",CHOOSE(O21,"một","hai","ba","bốn","năm","sáu","bảy","tám","chín")) | P23: =IF(P21=0,IF(AND(O21<>0,Q21<>0),"lẻ",""),CHOOSE(P21,"mười","hai","ba","bốn","năm","sáu","bảy","tám","chín"))
C24: =IF(C21=0,"","trăm") | D24: =IF(D21=0,"",IF(D21=1,"","mươi")) | E24: =IF(AND(E21=0,E22=0),"","tỷ") | F24: =IF(F21=0,"",IF(F21=1,"","mươi")) | I24: =IF(AND(I21=0,I22=0),"","triệu") -> triệu | J24: =IF(J21=0,"","trăm") | M24: =IF(M21=0,"",IF(M21=1,"","mươi")) | N24: =IF(AND(N21=0,N22=0),"","ngàn") | O24: =IF(O21=0,"","trăm") | P24: =IF(P21=0,"",IF(P21=1,"","mươi"))
B25: =UPPER(LEFT(TRIM(IF(A20=0,"không đồng.",C23&" "&C24&" "&D23&" "&D24&" "&E23&" "&E24&" "&#REF!&" "&#REF!&" "&F23&" "&F24&" "&I23&" "&I24&" "&J23&" "&J24&" "&M23&" "&M24&" "&N23&" "&N24&" "&O23&" "&O24&" "&P23&" "&P24&" "&Q23&" "&Q24)),1))&RIGHT(TRIM(IF(A20=0,"không đồng.",C23&" "&C24&" "&D23&" "&D24&" "&E23&" "&E24&" "&#REF!&" "&#REF!&" "&F23&" "&F24&" "&I23&" "&I24&" "&J23&" "&J24&" "&M23&" "&M24&" "&N23&" "&N24&" "&O23&" "&O24&" "&P23&" "&P24&" "&Q23&" "&Q24)),LEN(TRIM(IF(A20=0,"không đồng.",C23&" "&C24&" "&D23&" "&D24&" "&E23&" "&E24&" "&#REF!&" "&#REF!&" "&F23&" "&F24&" "&I23&" "&I24&" "&J23&" "&J24&" "&M23&" "&M24&" "&N23&" "&N24&" "&O23&" "&O24&" "&P23&" "&P24&" "&Q23&" "&Q24)))-1) -> #REF!
